<?xml version="1.0" ?>
<!-- =================================================================================== -->
<!-- |    This document was autogenerated by xacro from gunbo_robot.urdf.xacro         | -->
<!-- |    EDITING THIS FILE BY HAND IS NOT RECOMMENDED                                 | -->
<!-- =================================================================================== -->
<robot name="NKG_ROBOT" xmlns:xacro="http://www.ros.org/wiki/xacro">
  <material name="gray">
    <color rgba="0.5 0.5 0.5 2.0"/>
  </material>
  <material name="white">
    <color rgba="1.0 1.0 1.0 1.5"/>
  </material>
  <material name="black">
    <color rgba="0.0 0.0 0.0 1.5"/>
  </material>
  <link name="base_link">
    <visual>
      <geometry>
        <mesh filename="package://nkg_robot_description/meshes/gunbo_body.stl" scale="0.001 0.001 0.001"/>
      </geometry>
      <material name="white"/>
    </visual>
    <collision>
      <origin rpy="3.1415926536 0 0" xyz="0 0 0.1365"/>
      <geometry>
        <mesh filename="package://nkg_robot_description/meshes/gunbo_body.stl" scale="0.001 0.001 0.001"/>
      </geometry>
    </collision>
  </link>
  <link name="link_table">
    <visual>
      <geometry>
        <box size="0.442 0.806 0.03"/>
      </geometry>
      <material name="white"/>
    </visual>
    <collision>
      <origin rpy="0 0 0" xyz="0.201 0.158 -0.015"/>
      <geometry>
        <box size="0.442 0.806 0.03"/>
      </geometry>
      <material name="white"/>
    </collision>
  </link>
  <joint name="joint_table" type="fixed">
    <parent link="base_link"/>
    <child link="link_table"/>
    <origin rpy="0 0 0" xyz="0.103 0 0.86"/>
  </joint>
  <link name="link_wheel_l1">
    <visual>
      <geometry>
        <cylinder length="0.078" radius="0.1015"/>
      </geometry>
      <material name="white"/>
    </visual>
    <collision>
      <origin rpy="0 0 0" xyz="0 0 0"/>
      <geometry>
        <cylinder length="0.078" radius="0.1015"/>
      </geometry>
    </collision>
  </link>
  <joint name="wheel_l1" type="fixed">
    <parent link="base_link"/>
    <child link="link_wheel_l1"/>
    <origin rpy="1.5707963268 0 0" xyz="0.22 0.264 0.1015"/>
  </joint>
  <link name="link_wheel_l2">
    <visual>
      <geometry>
        <cylinder length="0.078" radius="0.1015"/>
      </geometry>
      <material name="white"/>
    </visual>
    <collision>
      <origin rpy="0 0 0" xyz="0 0 0"/>
      <geometry>
        <cylinder length="0.078" radius="0.1015"/>
      </geometry>
    </collision>
  </link>
  <joint name="wheel_l2" type="fixed">
    <parent link="base_link"/>
    <child link="link_wheel_l2"/>
    <origin rpy="1.5707963268 0 0" xyz="-0.22 0.264 0.1015"/>
  </joint>
  <link name="link_wheel_r1">
    <visual>
      <geometry>
        <cylinder length="0.078" radius="0.1015"/>
      </geometry>
      <material name="white"/>
    </visual>
    <collision>
      <origin rpy="0 0 0" xyz="0 0 0"/>
      <geometry>
        <cylinder length="0.078" radius="0.1015"/>
      </geometry>
    </collision>
  </link>
  <joint name="wheel_r1" type="fixed">
    <parent link="base_link"/>
    <child link="link_wheel_r1"/>
    <origin rpy="-1.5707963268 0 0" xyz="0.22 -0.264 0.1015"/>
  </joint>
  <link name="link_wheel_r2">
    <visual>
      <geometry>
        <cylinder length="0.078" radius="0.1015"/>
      </geometry>
      <material name="white"/>
    </visual>
    <collision>
      <origin rpy="0 0 0" xyz="0 0 0"/>
      <geometry>
        <cylinder length="0.078" radius="0.1015"/>
      </geometry>
    </collision>
  </link>
  <joint name="wheel_r2" type="fixed">
    <parent link="base_link"/>
    <child link="link_wheel_r2"/>
    <origin rpy="-1.5707963268 0 0" xyz="-0.22 -0.264 0.1015"/>
  </joint>
  <link name="link_head1">
    <visual>
      <geometry>
        <mesh filename="package://nkg_robot_description/meshes/gunbo_head_1.stl" scale="0.001 0.001 0.001"/>
      </geometry>
      <material name="white"/>
    </visual>
    <collision>
      <origin rpy="0 0 0" xyz="0 0 0"/>
      <geometry>
        <mesh filename="package://nkg_robot_description/meshes/gunbo_head_1.stl" scale="0.001 0.001 0.001"/>
      </geometry>
    </collision>
  </link>
  <joint name="head_1" type="fixed">
    <parent link="base_link"/>
    <child link="link_head1"/>
    <origin rpy="0 0 0" xyz="0.077 0 1.3365"/>
  </joint>
  <link name="link_head2">
    <visual>
      <geometry>
        <mesh filename="package://nkg_robot_description/meshes/gunbo_head_2.stl" scale="0.001 0.001 0.001"/>
      </geometry>
      <material name="white"/>
    </visual>
    <collision>
      <origin rpy="1.5707963268 0 1.5707963268" xyz="0 0 -0.189"/>
      <geometry>
        <mesh filename="package://nkg_robot_description/meshes/gunbo_head_2.stl" scale="0.001 0.001 0.001"/>
      </geometry>
    </collision>
  </link>
  <joint name="head_2" type="fixed">
    <parent link="link_head1"/>
    <child link="link_head2"/>
    <origin rpy="0 0 0" xyz="0 0 0.0945"/>
  </joint>
  <link name="link_head3">
    <visual>
      <geometry>
        <mesh filename="package://nkg_robot_description/meshes/gunbo_head_3.stl" scale="0.001 0.001 0.001"/>
      </geometry>
      <material name="white"/>
    </visual>
    <collision>
      <origin rpy="0 0 3.1415926536" xyz="0 0 0"/>
      <geometry>
        <mesh filename="package://nkg_robot_description/meshes/gunbo_head_3.stl" scale="0.001 0.001 0.001"/>
      </geometry>
    </collision>
  </link>
  <joint name="head_3" type="fixed">
    <parent link="link_head2"/>
    <child link="link_head3"/>
    <origin rpy="0 0 0" xyz="0 0 0.017"/>
  </joint>
  <link name="M8_link">
    <visual>
      <geometry>
        <mesh filename="package://nkg_robot_description/meshes/h42_20.stl" scale="0.001 0.001 0.001"/>
      </geometry>
      <material name="white"/>
    </visual>
    <collision>
      <origin rpy="-1.5707963268 0 0" xyz="0 0.084 0"/>
      <geometry>
        <mesh filename="package://nkg_robot_description/meshes/h42_20.stl" scale="0.001 0.001 0.001"/>
      </geometry>
    </collision>
  </link>
  <joint name="arm_l_base_joint" type="fixed">
    <parent link="base_link"/>
    <child link="M8_link"/>
    <origin rpy="0 0 0" xyz="0 0.225 1.2825"/>
  </joint>
  <link name="arml_1_1_link">
    <visual>
      <geometry>
        <mesh filename="package://nkg_robot_description/meshes/nkg_robot_description_A.stl" scale="0.001 0.001 0.001"/>
      </geometry>
      <material name="white"/>
    </visual>
    <collision>
      <origin rpy="-1.5707963268 0 0" xyz="0 0.0325 0"/>
      <geometry>
        <mesh filename="package://nkg_robot_description/meshes/nkg_robot_description_A.stl" scale="0.001 0.001 0.001"/>
      </geometry>
    </collision>
  </link>
  <joint name="M8_joint" type="revolute">
    <parent link="M8_link"/>
    <child link="arml_1_1_link"/>
    <origin rpy="0 0 0" xyz="0 0.084 0"/>
    <limit effort="30" lower="-2.0943951024" upper="2.0943951024" velocity="10"/>
    <axis xyz="0 1 0"/>
  </joint>
  <link name="arml_1_2_link">
    <visual>
      <geometry>
        <mesh filename="package://nkg_robot_description/meshes/nkg_robot_description_B.stl" scale="0.001 0.001 0.001"/>
      </geometry>
      <material name="white"/>
    </visual>
    <collision>
      <origin rpy="1.5707963268 0 0" xyz="0 0 0"/>
      <geometry>
        <mesh filename="package://nkg_robot_description/meshes/nkg_robot_description_B.stl" scale="0.001 0.001 0.001"/>
      </geometry>
    </collision>
  </link>
  <joint name="arml_1_1_link_joint" type="fixed">
    <parent link="arml_1_1_link"/>
    <child link="arml_1_2_link"/>
    <origin rpy="0 0 0" xyz="0 0.0325 0"/>
  </joint>
  <link name="M9_link">
    <visual>
      <geometry>
        <mesh filename="package://nkg_robot_description/meshes/h42_20.stl" scale="0.001 0.001 0.001"/>
      </geometry>
      <material name="white"/>
    </visual>
    <collision>
      <origin rpy="0 -1.5707963268 0" xyz="-0.042 0.021 0"/>
      <geometry>
        <mesh filename="package://nkg_robot_description/meshes/h42_20.stl" scale="0.001 0.001 0.001"/>
      </geometry>
    </collision>
  </link>
  <joint name="arml_1_2_link_joint" type="fixed">
    <parent link="arml_1_2_link"/>
    <child link="M9_link"/>
    <origin rpy="0 0 0" xyz="0 0.015 0"/>
  </joint>
  <link name="arml_2_1_link">
    <visual>
      <geometry>
        <mesh filename="package://nkg_robot_description/meshes/ARM_1.stl" scale="0.001 0.001 0.001"/>
      </geometry>
      <material name="white"/>
    </visual>
    <collision>
      <origin rpy="0 1.5707963268 -1.5707963268" xyz="0 0 -0.0145"/>
      <geometry>
        <mesh filename="package://nkg_robot_description/meshes/ARM_1.stl" scale="0.001 0.001 0.001"/>
      </geometry>
    </collision>
  </link>
  <joint name="M9_joint" type="revolute">
    <parent link="M9_link"/>
    <child link="arml_2_1_link"/>
    <origin rpy="0 0 0" xyz="0 0.021 0"/>
    <limit effort="30" lower="-2.0943951024" upper="2.0943951024" velocity="10"/>
    <axis xyz="-1 0 0"/>
  </joint>
  <link name="arml_2_2_link">
    <visual>
      <geometry>
        <mesh filename="package://nkg_robot_description/meshes/ARM_2.stl" scale="0.001 0.001 0.001"/>
      </geometry>
      <material name="white"/>
    </visual>
    <collision>
      <origin rpy="0 0 0.5235987756" xyz="0 0 -0.043525"/>
      <geometry>
        <mesh filename="package://nkg_robot_description/meshes/ARM_2.stl" scale="0.001 0.001 0.001"/>
      </geometry>
    </collision>
  </link>
  <joint name="arml_2_1_joint" type="fixed">
    <parent link="arml_2_1_link"/>
    <child link="arml_2_2_link"/>
    <origin rpy="0 0 0" xyz="0 0 -0.053"/>
  </joint>
  <link name="arml_2_3_link">
    <visual>
      <geometry>
        <mesh filename="package://nkg_robot_description/meshes/nkg_robot_description_B.stl" scale="0.001 0.001 0.001"/>
      </geometry>
      <material name="white"/>
    </visual>
    <collision>
      <origin rpy="0 0 0" xyz="0 0 0"/>
      <geometry>
        <mesh filename="package://nkg_robot_description/meshes/nkg_robot_description_B.stl" scale="0.001 0.001 0.001"/>
      </geometry>
    </collision>
  </link>
  <joint name="arml_2_2_joint" type="fixed">
    <parent link="arml_2_2_link"/>
    <child link="arml_2_3_link"/>
    <origin rpy="0 0 0" xyz="0 0 -0.08705"/>
  </joint>
  <link name="M10_link">
    <visual>
      <geometry>
        <mesh filename="package://nkg_robot_description/meshes/h42_20.stl" scale="0.001 0.001 0.001"/>
      </geometry>
      <material name="white"/>
    </visual>
    <collision>
      <origin rpy="0 -1.5707963268 0" xyz="-0.042 0 -0.021"/>
      <geometry>
        <mesh filename="package://nkg_robot_description/meshes/h42_20.stl" scale="0.001 0.001 0.001"/>
      </geometry>
    </collision>
  </link>
  <joint name="arml_2_3_joint" type="fixed">
    <parent link="arml_2_3_link"/>
    <child link="M10_link"/>
    <origin rpy="0 0 0" xyz="0 0 -0.015"/>
  </joint>
  <link name="arml_3_1_link">
    <visual>
      <geometry>
        <mesh filename="package://nkg_robot_description/meshes/ARM_1.stl" scale="0.001 0.001 0.001"/>
      </geometry>
      <material name="white"/>
    </visual>
    <collision>
      <origin rpy="0 1.5707963268 -1.5707963268" xyz="0 0 -0.0145"/>
      <geometry>
        <mesh filename="package://nkg_robot_description/meshes/ARM_1.stl" scale="0.001 0.001 0.001"/>
      </geometry>
    </collision>
  </link>
  <joint name="M10_joint" type="revolute">
    <parent link="M10_link"/>
    <child link="arml_3_1_link"/>
    <origin rpy="0 0 0" xyz="0 0 -0.021"/>
    <limit effort="30" lower="-0.5235987756" upper="2.0943951024" velocity="10"/>
    <axis xyz="-1 0 0"/>
  </joint>
  <link name="arml_3_2_link">
    <visual>
      <geometry>
        <mesh filename="package://nkg_robot_description/meshes/ARM_4.stl" scale="0.001 0.001 0.001"/>
      </geometry>
      <material name="white"/>
    </visual>
    <collision>
      <origin rpy="-3.1415926536 0 0" xyz="0 0 -0.0265"/>
      <geometry>
        <mesh filename="package://nkg_robot_description/meshes/ARM_4.stl" scale="0.001 0.001 0.001"/>
      </geometry>
    </collision>
  </link>
  <joint name="arml_3_1_joint" type="fixed">
    <parent link="arml_3_1_link"/>
    <child link="arml_3_2_link"/>
    <origin rpy="0 0 0" xyz="0 0 -0.053"/>
  </joint>
  <link name="arml_3_3_link">
    <visual>
      <geometry>
        <mesh filename="package://nkg_robot_description/meshes/ARM_3.stl" scale="0.001 0.001 0.001"/>
      </geometry>
      <material name="white"/>
    </visual>
    <collision>
      <origin rpy="0 -1.5707963268 1.5707963268" xyz="0 0 -0.0115"/>
      <geometry>
        <mesh filename="package://nkg_robot_description/meshes/ARM_3.stl" scale="0.001 0.001 0.001"/>
      </geometry>
    </collision>
  </link>
  <joint name="arml_3_2_joint" type="fixed">
    <parent link="arml_3_2_link"/>
    <child link="arml_3_3_link"/>
    <origin rpy="0 0 0" xyz="0 0 -0.053"/>
  </joint>
  <link name="M11_link">
    <visual>
      <geometry>
        <mesh filename="package://nkg_robot_description/meshes/m42_10.stl" scale="0.001 0.001 0.001"/>
      </geometry>
      <material name="white"/>
    </visual>
    <collision>
      <origin rpy="-1.5707963268 0 0" xyz="0 0 -0.066"/>
      <geometry>
        <mesh filename="package://nkg_robot_description/meshes/m42_10.stl" scale="0.001 0.001 0.001"/>
      </geometry>
    </collision>
  </link>
  <joint name="arml_3_3_joint" type="fixed">
    <parent link="arml_3_3_link"/>
    <child link="M11_link"/>
    <origin rpy="0 0 0" xyz="0 0 -0.005"/>
  </joint>
  <link name="arml_4_1_link">
    <visual>
      <geometry>
        <mesh filename="package://nkg_robot_description/meshes/nkg_robot_description_A.stl" scale="0.001 0.001 0.001"/>
      </geometry>
      <material name="white"/>
    </visual>
    <collision>
      <origin rpy="3.1415926536 0 0.5235987756" xyz="0 0 -0.0325"/>
      <geometry>
        <mesh filename="package://nkg_robot_description/meshes/nkg_robot_description_A.stl" scale="0.001 0.001 0.001"/>
      </geometry>
    </collision>
  </link>
  <joint name="M11_joint" type="revolute">
    <parent link="M11_link"/>
    <child link="arml_4_1_link"/>
    <origin rpy="0 0 0" xyz="0 0 -0.072"/>
    <limit effort="30" lower="-3.76991118432" upper="3.76991118432" velocity="10"/>
    <axis xyz="0 0 -1"/>
  </joint>
  <link name="arml_4_2_link">
    <visual>
      <geometry>
        <mesh filename="package://nkg_robot_description/meshes/nkg_robot_description_B.stl" scale="0.001 0.001 0.001"/>
      </geometry>
      <material name="white"/>
    </visual>
    <collision>
      <origin rpy="0 0 1.5707963268" xyz="0 0 0"/>
      <geometry>
        <mesh filename="package://nkg_robot_description/meshes/nkg_robot_description_B.stl" scale="0.001 0.001 0.001"/>
      </geometry>
    </collision>
  </link>
  <joint name="arml_4_1_joint" type="fixed">
    <parent link="arml_4_1_link"/>
    <child link="arml_4_2_link"/>
    <origin rpy="0 0 0" xyz="0 0 -0.0325"/>
  </joint>
  <link name="M12_link">
    <visual>
      <geometry>
        <mesh filename="package://nkg_robot_description/meshes/h42_20.stl" scale="0.001 0.001 0.001"/>
      </geometry>
      <material name="white"/>
    </visual>
    <collision>
      <origin rpy="0 -1.5707963268 -1.5707963268" xyz="0 0.042 -0.021"/>
      <geometry>
        <mesh filename="package://nkg_robot_description/meshes/h42_20.stl" scale="0.001 0.001 0.001"/>
      </geometry>
    </collision>
  </link>
  <joint name="arml_4_2_joint" type="fixed">
    <parent link="arml_4_2_link"/>
    <child link="M12_link"/>
    <origin rpy="0 0 0" xyz="0 0 -0.015"/>
  </joint>
  <link name="arml_5_1_link">
    <visual>
      <geometry>
        <mesh filename="package://nkg_robot_description/meshes/ARM_1.stl" scale="0.001 0.001 0.001"/>
      </geometry>
      <material name="white"/>
    </visual>
    <collision>
      <origin rpy="0 1.5707963268 0" xyz="0 0 -0.0145"/>
      <geometry>
        <mesh filename="package://nkg_robot_description/meshes/ARM_1.stl" scale="0.001 0.001 0.001"/>
      </geometry>
    </collision>
  </link>
  <joint name="M12_joint" type="revolute">
    <parent link="M12_link"/>
    <child link="arml_5_1_link"/>
    <origin rpy="0 0 0" xyz="0 0 -0.021"/>
    <limit effort="30" lower="-2.617993878" upper="0.5235987756" velocity="10"/>
    <axis xyz="0 1 0"/>
  </joint>
  <link name="arml_5_2_link">
    <visual>
      <geometry>
        <mesh filename="package://nkg_robot_description/meshes/ARM_3.stl" scale="0.001 0.001 0.001"/>
      </geometry>
      <material name="white"/>
    </visual>
    <collision>
      <origin rpy="0 -1.5707963268 0" xyz="0 0 -0.0115"/>
      <geometry>
        <mesh filename="package://nkg_robot_description/meshes/ARM_3.stl" scale="0.001 0.001 0.001"/>
      </geometry>
    </collision>
  </link>
  <joint name="arml_5_1_joint" type="fixed">
    <parent link="arml_5_1_link"/>
    <child link="arml_5_2_link"/>
    <origin rpy="0 0 0" xyz="0 0 -0.053"/>
  </joint>
  <link name="M13_link">
    <visual>
      <geometry>
        <mesh filename="package://nkg_robot_description/meshes/m42_10.stl" scale="0.001 0.001 0.001"/>
      </geometry>
      <material name="white"/>
    </visual>
    <collision>
      <origin rpy="-1.5707963268 0 0" xyz="0 0 -0.066"/>
      <geometry>
        <mesh filename="package://nkg_robot_description/meshes/m42_10.stl" scale="0.001 0.001 0.001"/>
      </geometry>
    </collision>
  </link>
  <joint name="arml_5_2_joint" type="fixed">
    <parent link="arml_5_2_link"/>
    <child link="M13_link"/>
    <origin rpy="0 0 0" xyz="0 0 -0.005"/>
  </joint>
  <link name="grip_l_box_link">
    <visual>
      <geometry>
        <mesh filename="package://nkg_robot_description/meshes/nkg_robot_description_BOX.stl" scale="0.001 0.001 0.001"/>
      </geometry>
      <material name="white"/>
    </visual>
    <collision>
      <origin rpy="0 0 1.5707963268" xyz="0 0 0"/>
      <geometry>
        <mesh filename="package://nkg_robot_description/meshes/nkg_robot_description_BOX.stl" scale="0.001 0.001 0.001"/>
      </geometry>
    </collision>
  </link>
  <joint name="M13_joint" type="revolute">
    <parent link="M13_link"/>
    <child link="grip_l_box_link"/>
    <origin rpy="0 0 0" xyz="0 0 -0.072"/>
    <limit effort="30" lower="-1.5707963268" upper="1.5707963268" velocity="10"/>
    <axis xyz="0 0 -1"/>
  </joint>
  <link name="grip_l_l_link">
    <visual>
      <geometry>
        <mesh filename="package://nkg_robot_description/meshes/nkg_robot_description_GRIPPER.stl" scale="0.001 0.001 0.001"/>
      </geometry>
      <material name="white"/>
    </visual>
    <collision>
      <origin rpy="1.5707963268 0 1.5707963268" xyz="0 -0.013 -0.005"/>
      <geometry>
        <mesh filename="package://nkg_robot_description/meshes/nkg_robot_description_GRIPPER.stl" scale="0.001 0.001 0.001"/>
      </geometry>
    </collision>
  </link>
  <!-- <joint name="grip_l_l_joint" type="prismatic"> -->
  <joint name="M14_joint" type="prismatic">
    <parent link="grip_l_box_link"/>
    <child link="grip_l_l_link"/>
    <origin rpy="0 0 0" xyz="0 0 -0.125"/>
    <axis xyz="0 1 0"/>
    <limit effort="300.0" lower="-0.0220" upper="0.013" velocity="1.0"/>
  </joint>
  <link name="grip_l_r_link">
    <visual>
      <geometry>
        <mesh filename="package://nkg_robot_description/meshes/nkg_robot_description_GRIPPER.stl" scale="0.001 0.001 0.001"/>
      </geometry>
      <material name="white"/>
    </visual>
    <collision>
      <origin rpy="1.5707963268 0 -1.5707963268" xyz="0 0.01 -0.005"/>
      <geometry>
        <mesh filename="package://nkg_robot_description/meshes/nkg_robot_description_GRIPPER.stl" scale="0.001 0.001 0.001"/>
      </geometry>
    </collision>
  </link>
  <joint name="grip_l_r_joint" type="fixed">
    <parent link="grip_l_box_link"/>
    <child link="grip_l_r_link"/>
    <origin rpy="0 0 0" xyz="0 0 -0.125"/>
  </joint>
  <!--         <xacro:macro_link name="grip_l_funnel_link" mesh="funnel.stl" xyz="0.04625 0 0" rpy="0 -${PI/2} 0"/> -->
  <!--         <xacro:joint_fixed name="grip_l_funnel_joint" link0="grip_l_r_link" link1="grip_l_funnel_link" xyz="0 0 -0.062" rpy="0 0 0"/> -->
  <!--         <link name="grip_l_ball"> -->
  <!--             <visual> -->
  <!--                 <origin xyz="0 0 0" rpy="0 0 0"/> -->
  <!--                 <geometry> -->
  <!--                     <sphere radius="0.047"/> -->
  <!--                 </geometry> -->
  <!--                 <material name="white"/> -->
  <!--             </visual> -->
  <!--             <collision> -->
  <!--                 <origin xyz="0 0 0" rpy="0 0 0"/> -->
  <!--                 <geometry> -->
  <!--                     <sphere radius="0.047"/> -->
  <!--                 </geometry> -->
  <!--             </collision> -->
  <!--         </link> -->
  <!--         <joint name="grip_l_ball_joint" type="fixed"> -->
  <!--             <parent link="grip_l_funnel_link"/> -->
  <!--             <child link="grip_l_ball"/> -->
  <!--             <origin xyz="-0.102 0 0" rpy="0 0 0"/> -->
  <!--         </joint> -->
  <!-- ============== gripper end ============== -->
  <link name="M1_link">
    <visual>
      <origin rpy="1.5707963268 0 0" xyz="0 -0.084 0"/>
      <geometry>
        <mesh filename="package://nkg_robot_description/meshes/h42_20.stl" scale="0.001 0.001 0.001"/>
      </geometry>
      <material name="white"/>
    </visual>
    <collision>
      <origin rpy="1.5707963268 0 0" xyz="0 -0.084 0"/>
      <geometry>
        <mesh filename="package://nkg_robot_description/meshes/h42_20.stl" scale="0.001 0.001 0.001"/>
      </geometry>
    </collision>
  </link>
  <joint name="arm_r_base_joint" type="fixed">
    <parent link="base_link"/>
    <child link="M1_link"/>
    <origin rpy="0 0 0" xyz="0 -0.225 1.2825"/>
  </joint>
  <link name="armr_1_1_link">
    <visual>
      <origin rpy="1.5707963268 0 0" xyz="0 -0.0325 0"/>
      <geometry>
        <mesh filename="package://nkg_robot_description/meshes/nkg_robot_description_A.stl" scale="0.001 0.001 0.001"/>
      </geometry>
      <material name="white"/>
    </visual>
    <collision>
      <origin rpy="1.5707963268 0 0" xyz="0 -0.0325 0"/>
      <geometry>
        <mesh filename="package://nkg_robot_description/meshes/nkg_robot_description_A.stl" scale="0.001 0.001 0.001"/>
      </geometry>
    </collision>
  </link>
  <joint name="M1_joint" type="revolute">
    <parent link="M1_link"/>
    <child link="armr_1_1_link"/>
    <origin rpy="0 0 0" xyz="0 -0.084 0"/>
    <limit effort="30" lower="-1.5707963268" upper="1.5707963268" velocity="10"/>
    <axis xyz="0 -1 0"/>
  </joint>
  <link name="armr_1_2_link">
    <visual>
      <origin rpy="-1.5707963268 0 0" xyz="0 0 0"/>
      <geometry>
        <mesh filename="package://nkg_robot_description/meshes/nkg_robot_description_B.stl" scale="0.001 0.001 0.001"/>
      </geometry>
      <material name="white"/>
    </visual>
    <collision>
      <origin rpy="-1.5707963268 0 0" xyz="0 0 0"/>
      <geometry>
        <mesh filename="package://nkg_robot_description/meshes/nkg_robot_description_B.stl" scale="0.001 0.001 0.001"/>
      </geometry>
    </collision>
  </link>
  <joint name="armr_1_1_link_joint" type="fixed">
    <parent link="armr_1_1_link"/>
    <child link="armr_1_2_link"/>
    <origin rpy="0 0 0" xyz="0 -0.0325 0"/>
  </joint>
  <link name="M2_link">
    <visual>
      <origin rpy="0 -1.5707963268 0" xyz="-0.042 -0.021 0"/>
      <geometry>
        <mesh filename="package://nkg_robot_description/meshes/h42_20.stl" scale="0.001 0.001 0.001"/>
      </geometry>
      <material name="white"/>
    </visual>
    <collision>
      <origin rpy="0 -1.5707963268 0" xyz="-0.042 -0.021 0"/>
      <geometry>
        <mesh filename="package://nkg_robot_description/meshes/h42_20.stl" scale="0.001 0.001 0.001"/>
      </geometry>
    </collision>
  </link>
  <joint name="armr_1_2_link_joint" type="fixed">
    <parent link="armr_1_2_link"/>
    <child link="M2_link"/>
    <origin rpy="0 0 0" xyz="0 -0.015 0"/>
  </joint>
  <link name="armr_2_1_link">
    <visual>
      <origin rpy="0 1.5707963268 -1.5707963268" xyz="0 0 -0.0145"/>
      <geometry>
        <mesh filename="package://nkg_robot_description/meshes/ARM_1.stl" scale="0.001 0.001 0.001"/>
      </geometry>
      <material name="white"/>
    </visual>
    <collision>
      <origin rpy="0 1.5707963268 -1.5707963268" xyz="0 0 -0.0145"/>
      <geometry>
        <mesh filename="package://nkg_robot_description/meshes/ARM_1.stl" scale="0.001 0.001 0.001"/>
      </geometry>
    </collision>
  </link>
  <joint name="M2_joint" type="revolute">
    <parent link="M2_link"/>
    <child link="armr_2_1_link"/>
    <origin rpy="0 0 0" xyz="0 -0.021 0"/>
    <limit effort="30" lower="-1.5707963268" upper="1.5707963268" velocity="10"/>
    <axis xyz="-1 0 0"/>
  </joint>
  <link name="armr_2_2_link">
    <visual>
      <origin rpy="0 0 0.5235987756" xyz="0 0 -0.043525"/>
      <geometry>
        <mesh filename="package://nkg_robot_description/meshes/ARM_2.stl" scale="0.001 0.001 0.001"/>
      </geometry>
      <material name="white"/>
    </visual>
    <collision>
      <origin rpy="0 0 0.5235987756" xyz="0 0 -0.043525"/>
      <geometry>
        <mesh filename="package://nkg_robot_description/meshes/ARM_2.stl" scale="0.001 0.001 0.001"/>
      </geometry>
    </collision>
  </link>
  <joint name="armr_2_1_joint" type="fixed">
    <parent link="armr_2_1_link"/>
    <child link="armr_2_2_link"/>
    <origin rpy="0 0 0" xyz="0 0 -0.053"/>
  </joint>
  <link name="armr_2_3_link">
    <visual>
      <origin rpy="0 0 0" xyz="0 0 0"/>
      <geometry>
        <mesh filename="package://nkg_robot_description/meshes/nkg_robot_description_B.stl" scale="0.001 0.001 0.001"/>
      </geometry>
      <material name="white"/>
    </visual>
    <collision>
      <origin rpy="0 0 0" xyz="0 0 0"/>
      <geometry>
        <mesh filename="package://nkg_robot_description/meshes/nkg_robot_description_B.stl" scale="0.001 0.001 0.001"/>
      </geometry>
    </collision>
  </link>
  <joint name="armr_2_2_joint" type="fixed">
    <parent link="armr_2_2_link"/>
    <child link="armr_2_3_link"/>
    <origin rpy="0 0 0" xyz="0 0 -0.08705"/>
  </joint>
  <link name="M3_link">
    <visual>
      <origin rpy="0 -1.5707963268 0" xyz="-0.042 0 -0.021"/>
      <geometry>
        <mesh filename="package://nkg_robot_description/meshes/h42_20.stl" scale="0.001 0.001 0.001"/>
      </geometry>
      <material name="white"/>
    </visual>
    <collision>
      <origin rpy="0 -1.5707963268 0" xyz="-0.042 0 -0.021"/>
      <geometry>
        <mesh filename="package://nkg_robot_description/meshes/h42_20.stl" scale="0.001 0.001 0.001"/>
      </geometry>
    </collision>
  </link>
  <joint name="armr_2_3_joint" type="fixed">
    <parent link="armr_2_3_link"/>
    <child link="M3_link"/>
    <origin rpy="0 0 0" xyz="0 0 -0.015"/>
  </joint>
  <link name="armr_3_1_link">
    <visual>
      <origin rpy="0 1.5707963268 -1.5707963268" xyz="0 0 -0.0145"/>
      <geometry>
        <mesh filename="package://nkg_robot_description/meshes/ARM_1.stl" scale="0.001 0.001 0.001"/>
      </geometry>
      <material name="white"/>
    </visual>
    <collision>
      <origin rpy="0 1.5707963268 -1.5707963268" xyz="0 0 -0.0145"/>
      <geometry>
        <mesh filename="package://nkg_robot_description/meshes/ARM_1.stl" scale="0.001 0.001 0.001"/>
      </geometry>
    </collision>
  </link>
  <joint name="M3_joint" type="revolute">
    <parent link="M3_link"/>
    <child link="armr_3_1_link"/>
    <origin rpy="0 0 0" xyz="0 0 -0.021"/>
    <limit effort="30" lower="-2.617993878" upper="0.5235987756" velocity="10"/>
    <axis xyz="-1 0 0"/>
  </joint>
  <link name="armr_3_2_link">
    <visual>
      <origin rpy="-3.1415926536 0 0" xyz="0 0 -0.0265"/>
      <geometry>
        <mesh filename="package://nkg_robot_description/meshes/ARM_4.stl" scale="0.001 0.001 0.001"/>
      </geometry>
      <material name="white"/>
    </visual>
    <collision>
      <origin rpy="-3.1415926536 0 0" xyz="0 0 -0.0265"/>
      <geometry>
        <mesh filename="package://nkg_robot_description/meshes/ARM_4.stl" scale="0.001 0.001 0.001"/>
      </geometry>
    </collision>
  </link>
  <joint name="armr_3_1_joint" type="fixed">
    <parent link="armr_3_1_link"/>
    <child link="armr_3_2_link"/>
    <origin rpy="0 0 0" xyz="0 0 -0.053"/>
  </joint>
  <link name="armr_3_3_link">
    <visual>
      <origin rpy="0 -1.5707963268 1.5707963268" xyz="0 0 -0.0115"/>
      <geometry>
        <mesh filename="package://nkg_robot_description/meshes/ARM_3.stl" scale="0.001 0.001 0.001"/>
      </geometry>
      <material name="white"/>
    </visual>
    <collision>
      <origin rpy="0 -1.5707963268 1.5707963268" xyz="0 0 -0.0115"/>
      <geometry>
        <mesh filename="package://nkg_robot_description/meshes/ARM_3.stl" scale="0.001 0.001 0.001"/>
      </geometry>
    </collision>
  </link>
  <joint name="armr_3_2_joint" type="fixed">
    <parent link="armr_3_2_link"/>
    <child link="armr_3_3_link"/>
    <origin rpy="0 0 0" xyz="0 0 -0.053"/>
  </joint>
  <link name="M4_link">
    <visual>
      <origin rpy="-1.5707963268 0 0" xyz="0 0 -0.066"/>
      <geometry>
        <mesh filename="package://nkg_robot_description/meshes/m42_10.stl" scale="0.001 0.001 0.001"/>
      </geometry>
      <material name="white"/>
    </visual>
    <collision>
      <origin rpy="-1.5707963268 0 0" xyz="0 0 -0.066"/>
      <geometry>
        <mesh filename="package://nkg_robot_description/meshes/m42_10.stl" scale="0.001 0.001 0.001"/>
      </geometry>
    </collision>
  </link>
  <joint name="armr_3_3_joint" type="fixed">
    <parent link="armr_3_3_link"/>
    <child link="M4_link"/>
    <origin rpy="0 0 0" xyz="0 0 -0.005"/>
  </joint>
  <link name="armr_4_1_link">
    <visual>
      <origin rpy="3.1415926536 0 0.5235987756" xyz="0 0 -0.0325"/>
      <geometry>
        <mesh filename="package://nkg_robot_description/meshes/nkg_robot_description_A.stl" scale="0.001 0.001 0.001"/>
      </geometry>
      <material name="white"/>
    </visual>
    <collision>
      <origin rpy="3.1415926536 0 0.5235987756" xyz="0 0 -0.0325"/>
      <geometry>
        <mesh filename="package://nkg_robot_description/meshes/nkg_robot_description_A.stl" scale="0.001 0.001 0.001"/>
      </geometry>
    </collision>
  </link>
  <joint name="M4_joint" type="revolute">
    <parent link="M4_link"/>
    <child link="armr_4_1_link"/>
    <origin rpy="0 0 0" xyz="0 0 -0.072"/>
    <limit effort="30" lower="-3.76991118432" upper="3.76991118432" velocity="10"/>
    <axis xyz="0 0 -1"/>
  </joint>
  <link name="armr_4_2_link">
    <visual>
      <origin rpy="0 0 0" xyz="0 0 0"/>
      <geometry>
        <mesh filename="package://nkg_robot_description/meshes/nkg_robot_description_B.stl" scale="0.001 0.001 0.001"/>
      </geometry>
      <material name="white"/>
    </visual>
    <collision>
      <origin rpy="0 0 0" xyz="0 0 0"/>
      <geometry>
        <mesh filename="package://nkg_robot_description/meshes/nkg_robot_description_B.stl" scale="0.001 0.001 0.001"/>
      </geometry>
    </collision>
  </link>
  <joint name="armr_4_1_joint" type="fixed">
    <parent link="armr_4_1_link"/>
    <child link="armr_4_2_link"/>
    <origin rpy="0 0 0" xyz="0 0 -0.0325"/>
  </joint>
  <link name="M5_link">
    <visual>
      <origin rpy="0 -1.5707963268 1.5707963268" xyz="0 -0.042 -0.021"/>
      <geometry>
        <mesh filename="package://nkg_robot_description/meshes/h42_20.stl" scale="0.001 0.001 0.001"/>
      </geometry>
      <material name="white"/>
    </visual>
    <collision>
      <origin rpy="0 -1.5707963268 1.5707963268" xyz="0 -0.042 -0.021"/>
      <geometry>
        <mesh filename="package://nkg_robot_description/meshes/h42_20.stl" scale="0.001 0.001 0.001"/>
      </geometry>
    </collision>
  </link>
  <joint name="armr_4_2_joint" type="fixed">
    <parent link="armr_4_2_link"/>
    <child link="M5_link"/>
    <origin rpy="0 0 0" xyz="0 0 -0.015"/>
  </joint>
  <link name="armr_5_1_link">
    <visual>
      <origin rpy="0 1.5707963268 3.1415926536" xyz="0 0 -0.0145"/>
      <geometry>
        <mesh filename="package://nkg_robot_description/meshes/ARM_1.stl" scale="0.001 0.001 0.001"/>
      </geometry>
      <material name="white"/>
    </visual>
    <collision>
      <origin rpy="0 1.5707963268 3.1415926536" xyz="0 0 -0.0145"/>
      <geometry>
        <mesh filename="package://nkg_robot_description/meshes/ARM_1.stl" scale="0.001 0.001 0.001"/>
      </geometry>
    </collision>
  </link>
  <joint name="M5_joint" type="revolute">
    <parent link="M5_link"/>
    <child link="armr_5_1_link"/>
    <origin rpy="0 0 0" xyz="0 0 -0.021"/>
    <limit effort="30" lower="-0.5235987756" upper="2.617993878" velocity="10"/>
    <axis xyz="0 -1 0"/>
  </joint>
  <link name="armr_5_2_link">
    <visual>
      <origin rpy="0 -1.5707963268 0" xyz="0 0 -0.0115"/>
      <geometry>
        <mesh filename="package://nkg_robot_description/meshes/ARM_3.stl" scale="0.001 0.001 0.001"/>
      </geometry>
      <material name="white"/>
    </visual>
    <collision>
      <origin rpy="0 -1.5707963268 0" xyz="0 0 -0.0115"/>
      <geometry>
        <mesh filename="package://nkg_robot_description/meshes/ARM_3.stl" scale="0.001 0.001 0.001"/>
      </geometry>
    </collision>
  </link>
  <joint name="armr_5_1_joint" type="fixed">
    <parent link="armr_5_1_link"/>
    <child link="armr_5_2_link"/>
    <origin rpy="0 0 0" xyz="0 0 -0.053"/>
  </joint>
  <link name="M6_link">
    <visual>
      <origin rpy="-1.5707963268 0 0" xyz="0 0 -0.066"/>
      <geometry>
        <mesh filename="package://nkg_robot_description/meshes/m42_10.stl" scale="0.001 0.001 0.001"/>
      </geometry>
      <material name="white"/>
    </visual>
    <collision>
      <origin rpy="-1.5707963268 0 0" xyz="0 0 -0.066"/>
      <geometry>
        <mesh filename="package://nkg_robot_description/meshes/m42_10.stl" scale="0.001 0.001 0.001"/>
      </geometry>
    </collision>
  </link>
  <joint name="armr_5_2_joint" type="fixed">
    <parent link="armr_5_2_link"/>
    <child link="M6_link"/>
    <origin rpy="0 0 0" xyz="0 0 -0.005"/>
  </joint>
  <link name="grip_r_box_link">
    <visual>
      <origin rpy="0 0 -1.5707963268" xyz="0 0 0"/>
      <geometry>
        <mesh filename="package://nkg_robot_description/meshes/nkg_robot_description_BOX.stl" scale="0.001 0.001 0.001"/>
      </geometry>
      <material name="white"/>
    </visual>
    <collision>
      <origin rpy="0 0 -1.5707963268" xyz="0 0 0"/>
      <geometry>
        <mesh filename="package://nkg_robot_description/meshes/nkg_robot_description_BOX.stl" scale="0.001 0.001 0.001"/>
      </geometry>
    </collision>
  </link>
  <joint name="M6_joint" type="revolute">
    <parent link="M6_link"/>
    <child link="grip_r_box_link"/>
    <origin rpy="0 0 0" xyz="0 0 -0.072"/>
    <limit effort="30" lower="-1.5707963268" upper="1.5707963268" velocity="10"/>
    <axis xyz="0 0 -1"/>
  </joint>
  <link name="grip_r_l_link">
    <visual>
      <origin rpy="1.5707963268 0 1.5707963268" xyz="0 -0.01 -0.08"/>
      <geometry>
        <mesh filename="package://nkg_robot_description/meshes/nkg_robot_description_GRIPPER.stl" scale="0.001 0.001 0.001"/>
      </geometry>
      <material name="white"/>
    </visual>
    <collision>
      <origin rpy="1.5707963268 0 1.5707963268" xyz="0 -0.01 -0.08"/>
      <geometry>
        <mesh filename="package://nkg_robot_description/meshes/nkg_robot_description_GRIPPER.stl" scale="0.001 0.001 0.001"/>
      </geometry>
    </collision>
  </link>
  <joint name="grip_r_l_joint" type="fixed">
    <parent link="grip_r_box_link"/>
    <child link="grip_r_l_link"/>
    <origin rpy="0 0 0" xyz="0 0 -0.0515"/>
    <!-- <axis xyz="0 1 0"/> -->
    <!-- <limit effort="300.0" lower="-0.03" upper="0" velocity="1.0"/> -->
  </joint>
  <link name="grip_r_r_link">
    <visual>
      <origin rpy="1.5707963268 0 -1.5707963268" xyz="0 0.01 -0.08"/>
      <geometry>
        <mesh filename="package://nkg_robot_description/meshes/nkg_robot_description_GRIPPER.stl" scale="0.001 0.001 0.001"/>
      </geometry>
      <material name="white"/>
    </visual>
    <collision>
      <origin rpy="1.5707963268 0 -1.5707963268" xyz="0 0.01 -0.08"/>
      <geometry>
        <mesh filename="package://nkg_robot_description/meshes/nkg_robot_description_GRIPPER.stl" scale="0.001 0.001 0.001"/>
      </geometry>
    </collision>
  </link>
  <joint name="grip_r_r_joint" type="fixed">
    <parent link="grip_r_box_link"/>
    <child link="grip_r_r_link"/>
    <origin rpy="0 0 0" xyz="0 0 -0.0515"/>
  </joint>
  <link name="grip_r_funnel_link">
    <visual>
      <origin rpy="0 -1.5707963268 0" xyz="0.04625 0 0"/>
      <geometry>
        <mesh filename="package://nkg_robot_description/meshes/funnel.stl" scale="0.001 0.001 0.001"/>
      </geometry>
      <material name="white"/>
    </visual>
    <collision>
      <origin rpy="0 -1.5707963268 0" xyz="0.04625 0 0"/>
      <geometry>
        <mesh filename="package://nkg_robot_description/meshes/funnel.stl" scale="0.001 0.001 0.001"/>
      </geometry>
    </collision>
  </link>
  <joint name="grip_r_funnel_joint" type="fixed">
    <parent link="grip_r_r_link"/>
    <child link="grip_r_funnel_link"/>
    <origin rpy="0 0 0" xyz="0 0 -0.062"/>
  </joint>
  <link name="grip_r_ball">
    <visual>
      <origin rpy="0 0 0" xyz="0 0 0"/>
      <geometry>
        <sphere radius="0.039"/>
      </geometry>
      <material name="white"/>
    </visual>
    <collision>
      <origin rpy="0 0 0" xyz="0.039 0 0"/>
      <geometry>
        <sphere radius="0.025"/>
      </geometry>
    </collision>
  </link>
  <joint name="grip_r_ball_joint" type="fixed">
    <parent link="grip_r_funnel_link"/>
    <child link="grip_r_ball"/>
    <origin rpy="0 0 0" xyz="-0.089 0 0"/>
  </joint>
  <!-- ============== gripper end ============== -->
</robot>

